<?xml version="1.0"?>
<robot name="testarm">
  <link name="base">
    <inertial>
      <origin rpy = "0 0 0" xyz = "0 0 0" />
      <mass value = "0.0001" />
      <inertia ixx = "0.0001" ixy = "0" ixz = "0" iyy = "0.0001" iyz = "0" izz = "0.0001" />
    </inertial>
  </link>
  <link name="stand">
    <contact>
      <lateral_friction value = "1" />
    </contact>
    <inertial>
      <origin rpy = "0 0 0" xyz = "0.000 0.000 0.010" />
        <mass value = "2000" />
        <inertia ixx = "0.8" ixy = "0" ixz = "0" iyy = "0.8" iyz = "0" izz = "0.8" />
    </inertial>
    <visual>
      <origin rpy="0 0 0" xyz="0 0 0.010"/>
      <geometry>
        <box size="0.03 0.03 0.02"/>
      </geometry>
      <material name="White">
        <color rgba="1 1 1 1" />
      </material>
    </visual>
    <collision>
      <origin rpy = "0 0 0" xyz = "0.000 0.000 0.010" />
      <geometry>
        <box size = "0.03 0.03 0.020" />
      </geometry>
    </collision>
  </link>
  <joint name="base_stand" type="fixed" >
    <parent link = "base" />
    <child link = "stand" />
    <origin rpy = "0 0 0" xyz = "0.000 0.000 0.000" />
  </joint>
  <link name="arm1">
    <inertial>
      <origin rpy = "0 0 0" xyz = "0.000 0.000 0.030" />
        <mass value = "0.040" />
        <inertia ixx = "0.01.5" ixy = "0" ixz = "0" iyy = "0.01.5" iyz = "0" izz = "0.01" />
    </inertial>
    <visual>
      <origin rpy="0 0 0" xyz="0 0 0.030"/>
      <geometry>
        <box size="0.01 0.01 0.06"/>
      </geometry>
      <material name="Green">
        <color rgba="0 1 0 1" />
      </material>
    </visual>
    <collision>
      <origin rpy = "0 0 0" xyz = "0.000 0.000 0.03" />
      <geometry>
        <box size = "0.010 0.010 0.060" />
      </geometry>
    </collision>
  </link>
  <joint name="stand_arm1" type="revolute" >
    <parent link = "stand" />
    <child link = "arm1" />
    <origin rpt = "0 0 0" xyz = "0 0 0.02" />
    <axis xyz = "0 0 1" />
    <limit effort="10000.0" lower="-3.15" upper="3.15" velocity="0.5"/>
  </joint>
  <link name="arm2">
    <inertial>
      <origin rpy = "0 0 0" xyz = "0.000 0.000 0.030" />
        <mass value = "0.040" />
        <inertia ixx = "0.015" ixy = "0" ixz = "0" iyy = "0.015" iyz = "0" izz = "0.01" />
    </inertial>
    <visual>
      <origin rpy="0 0 0" xyz="0 0 0.03"/>
      <geometry>
        <box size="0.01 0.01 0.06"/>
      </geometry>
      <material name="Blue">
        <color rgba="0 0 1 1" />
      </material>
    </visual>
    <collision>
      <origin rpy = "0 0 0" xyz = "0.000 0.000 0.03" />
      <geometry>
        <box size = "0.010 0.010 0.060" />
      </geometry>
    </collision>
  </link>
  <joint name="arm1_arm2" type="revolute" >
    <parent link = "arm1" />
    <child link = "arm2" />
    <origin rpy = "0 0 0" xyz = "0.000 0.000 0.06" />
    <limit effort="10000.0" lower="-3.15" upper="3.15" velocity="0.5"/>
  </joint>
  <link name="arm3">
    <inertial>
      <origin rpy = "0 0 0" xyz = "0.000 0.000 0.03" />
        <mass value = "0.040" />
        <inertia ixx = "0.015" ixy = "0" ixz = "0" iyy = "0.015" iyz = "0" izz = "0.01" />
    </inertial>
    <visual>
      <origin rpy="0 0 0" xyz="0 0 0.03"/>
      <geometry>
        <box size="0.01 0.01 0.06"/>
      </geometry>
      <material name="Red">
        <color rgba="1 0 0 1" />
      </material>
    </visual>
    <collision>
      <origin rpy = "0 0 0" xyz = "0.000 0.000 0.03" />
      <geometry>
        <box size = "0.010 0.010 0.060" />
      </geometry>
    </collision>
  </link>
  <joint name="arm2_arm3" type="revolute" >
    <parent link = "arm2" />
    <child link = "arm3" />
    <origin rpy = "0 0 0" xyz = "0.000 0.000 0.06" />
    <limit effort="10000.0" lower="-3.15" upper="3.15" velocity="0.5"/>
  </joint>
  <link name="arm4">
    <inertial>
      <origin rpy = "0 0 0" xyz = "0.000 0.000 0.03" />
        <mass value = "0.040" />
        <inertia ixx = "0.015" ixy = "0" ixz = "0" iyy = "0.015" iyz = "0" izz = "0.01" />
    </inertial>
    <visual>
      <origin rpy="0 0 0" xyz="0 0 0.03"/>
      <geometry>
        <box size="0.01 0.01 0.06"/>
      </geometry>
      <material name="Yellow">
        <color rgba="1 1 0 1" />
      </material>
    </visual>
    <collision>
      <origin rpy = "0 0 0" xyz = "0.000 0.000 0.03" />
      <geometry>
        <box size = "0.010 0.010 0.06" />
      </geometry>
    </collision>
  </link>
  <joint name="arm3_arm4" type="revolute" >
    <parent link = "arm3" />
    <child link = "arm4" />
    <origin rpy = "0 0 0" xyz = "0.000 0.000 0.06" />
    <limit effort="10000.0" lower="-3.15" upper="3.15" velocity="0.5"/>
  </joint>
  <link name="gripper1">
    <inertial>
      <origin rpy = "0 0 0" xyz = "0.000 0.000 0.005" />
        <mass value = "0.020" />
        <inertia ixx = "0.01" ixy = "0" ixz = "0" iyy = "0.01" iyz = "0" izz = "0.01" />
    </inertial>
    <visual>
      <origin rpy="0 0 0" xyz="0 0 0.005"/>
      <geometry>
        <box size="0.04 0.01 0.01"/>
      </geometry>
      <material name="Black">
        <color rgba="0 0 0 1" />
      </material>
    </visual>
    <collision>
      <origin rpy = "0 0 0" xyz = "0.000 0.000 0.005" />
      <geometry>
        <box size = "0.04 0.010 0.010" />
      </geometry>
    </collision>
  </link>
  <joint name="arm4_gripper1" type="fixed" >
    <parent link = "arm4" />
    <child link = "gripper1" />
    <origin rpy = "0 0 0" xyz = "0.000 0.000 0.060" />
  </joint>
  <link name="gripper2">
    <contact>
      <lateral_friction value = "1" />
    </contact>
    <inertial>
      <origin rpy = "0 0 0" xyz = "0.000 0.000 0.0075" />
        <mass value = "0.003" />
        <inertia ixx = "0.01" ixy = "0" ixz = "0" iyy = "0.005" iyz = "0" izz = "0.005" />
    </inertial>
    <visual>
      <origin rpy="0 0 0" xyz="0 0 0.0075"/>
      <geometry>
        <box size="0.005 0.01 0.015"/>
      </geometry>
      <material name="Black">
        <color rgba="0 0 0 1" />
      </material>
    </visual>
    <collision>
      <origin rpy = "0 0 0" xyz = "0.000 0.000 0.0075" />
      <geometry>
        <box size = "0.005 0.010 0.015" />
      </geometry>
    </collision>
  </link>
  <joint name="gripper1_gripper2" type="prismatic" >
    <parent link = "gripper1" />
    <child link = "gripper2" />
    <origin rpy = "0 0 0" xyz = "-0.0175 0.000 0.01" />
    <limit effort="10000.0" lower="0" upper="0.015" velocity="0.5"/>
  </joint>
  <link name="gripper3">
    <contact>
      <lateral_friction value = "1" />
    </contact>
    <inertial>
      <origin rpy = "0 0 0" xyz = "0.000 0.000 0.0075" />
        <mass value = "0.003" />
        <inertia ixx = "0.01" ixy = "0" ixz = "0" iyy = "0.005" iyz = "0" izz = "0.005" />
    </inertial>
    <visual>
      <origin rpy="0 0 0" xyz="0 0 0.0075"/>
      <geometry>
        <box size="0.005 0.01 0.015"/>
      </geometry>
      <material name="Black">
        <color rgba="0 0 0 1" />
      </material>
    </visual>
    <collision>
      <origin rpy = "0 0 0" xyz = "0.000 0.000 0.0075" />
      <geometry>
        <box size = "0.005 0.010 0.015" />
      </geometry>
    </collision>
  </link>
  <joint name="gripper1_gripper3" type="prismatic" >
    <parent link = "gripper1" />
    <child link = "gripper3" />
    <origin rpy = "0 0 0" xyz = "0.0175 0.000 0.01" />
    <limit effort="10000.0" lower="-0.015" upper="0" velocity="0.5"/>
  </joint>
</robot>
