<?xml version="1.0"?>
<robot name="testarm">
  <link name="base">
    <inertial>
      <origin rpy = "0 0 0" xyz = "0 0 0" />
      <mass value = "0.0001" />
      <inertia ixx = "0.0001" ixy = "0" ixz = "0" iyy = "0.0001" iyz = "0" izz = "0.0001" />
    </inertial>
  </link>
  <link name="stand">
    <inertial>
      <origin rpy = "0 0 0" xyz = "0.000 0.000 0.010" />
        <mass value = "2000" />
        <inertia ixx = "0.8" ixy = "0" ixz = "0" iyy = "0.8" iyz = "0" izz = "0.8" />
    </inertial>
    <visual>
      <origin rpy="0 0 0" xyz="0 0 0.010"/>
      <geometry>
        <box size="3 3 0.02"/>
      </geometry>
      <material name="White">
        <color rgba="1 1 1 1" />
      </material>
    </visual>
    <collision>
      <origin rpy = "0 0 0" xyz = "0.000 0.000 0.010" />
      <geometry>
        <box size = "3 3 0.020" />
      </geometry>
    </collision>
  </link>
  <joint name="base_stand" type="fixed" >
    <parent link = "base" />
    <child link = "stand" />
    <origin rpy = "0 0 0" xyz = "0.000 0.000 0.000" />
  </joint>
  <link name="arm1">
    <inertial>
      <origin rpy = "0 0 0" xyz = "0.000 0.000 0.015" />
        <mass value = "0.020" />
        <inertia ixx = "0.01" ixy = "0" ixz = "0" iyy = "0.01" iyz = "0" izz = "0.01" />
    </inertial>
    <visual>
      <origin rpy="0 0 0" xyz="0 0 0.015"/>
      <geometry>
        <box size="0.01 0.01 0.03"/>
      </geometry>
      <material name="Green">
        <color rgba="0 1 0 1" />
      </material>
    </visual>
    <collision>
      <origin rpy = "0 0 0" xyz = "0.000 0.000 0.015" />
      <geometry>
        <box size = "0.010 0.010 0.030" />
      </geometry>
    </collision>
  </link>
  <joint name="stand_arm1" type="revolute" >
    <parent link = "stand" />
    <child link = "arm1" />
    <origin rpt = "0 0 0" xyz = "0 0 0.02" />
    <axis xyz = "0 0 1" />
    <limit effort="10000.0" lower="-3.14" upper="3.14" velocity="0.5"/>
  </joint>
  <link name="arm2">
    <inertial>
      <origin rpy = "0 0 0" xyz = "0.000 0.000 0.015" />
        <mass value = "0.020" />
        <inertia ixx = "0.01" ixy = "0" ixz = "0" iyy = "0.01" iyz = "0" izz = "0.01" />
    </inertial>
    <visual>
      <origin rpy="0 0 0" xyz="0 0 0.015"/>
      <geometry>
        <box size="0.01 0.01 0.03"/>
      </geometry>
      <material name="Blue">
        <color rgba="0 0 1 1" />
      </material>
    </visual>
    <collision>
      <origin rpy = "0 0 0" xyz = "0.000 0.000 0.015" />
      <geometry>
        <box size = "0.010 0.010 0.030" />
      </geometry>
    </collision>
  </link>
  <joint name="arm1_arm2" type="revolute" >
    <parent link = "arm1" />
    <child link = "arm2" />
    <origin rpy = "0 0 0" xyz = "0.000 0.000 0.03" />
    <limit effort="10000.0" lower="-1.57" upper="1.57" velocity="0.5"/>
  </joint>
  <link name="arm3">
    <inertial>
      <origin rpy = "0 0 0" xyz = "0.000 0.000 0.015" />
        <mass value = "0.020" />
        <inertia ixx = "0.01" ixy = "0" ixz = "0" iyy = "0.01" iyz = "0" izz = "0.01" />
    </inertial>
    <visual>
      <origin rpy="0 0 0" xyz="0 0 0.015"/>
      <geometry>
        <box size="0.01 0.01 0.03"/>
      </geometry>
      <material name="Red">
        <color rgba="1 0 0 1" />
      </material>
    </visual>
    <collision>
      <origin rpy = "0 0 0" xyz = "0.000 0.000 0.015" />
      <geometry>
        <box size = "0.010 0.010 0.030" />
      </geometry>
    </collision>
  </link>
  <joint name="arm2_arm3" type="revolute" >
    <parent link = "arm2" />
    <child link = "arm3" />
    <origin rpy = "0 0 0" xyz = "0.000 0.000 0.03" />
    <limit effort="10000.0" lower="-1.57" upper="1.57" velocity="0.5"/>
  </joint>
</robot>
